(.venv) C:\Git\Repositories\Privat\BC-App-Updater>python main.py
DEBUG:utils.credential_manager:Initializing credential manager
DEBUG:utils.credential_manager:Generating encryption key
DEBUG:utils.credential_manager:Encryption key generated successfully
DEBUG:utils.credential_manager:Attempting to load credentials from server_credentials.enc
DEBUG:utils.credential_manager:Decrypting credentials data
INFO:utils.credential_manager:Successfully loaded credentials for 1 servers
DEBUG:utils.credential_manager:Credential manager initialized successfully
DEBUG:__main__:Starting publish process
DEBUG:__main__:Selected configs: 1
DEBUG:__main__:Progress update: Starting deployment process...
DEBUG:__main__:Progress update: Checking credentials for Local...
DEBUG:__main__:Checking credentials for server: http://opitzybc_BC
INFO:utils.credential_manager:Retrieved credentials for server: http://opitzybc_BC
DEBUG:__main__:Using existing credentials for http://opitzybc_BC
DEBUG:__main__:Progress update: âœ“ Using stored credentials for Local
DEBUG:__main__:Progress update:
Starting deployment to selected servers...
DEBUG:__main__:Creating worker thread
DEBUG:__main__:PublishWorker initialized
DEBUG:__main__:Starting PublishWorker thread
DEBUG:__main__:Processing server: http://opitzybc_BC
INFO:utils.credential_manager:Retrieved credentials for server: http://opitzybc_BC
DEBUG:__main__:Publishing to http://opitzybc_BC
DEBUG:__main__:Worker thread started
DEBUG:__main__:Queue result received: progress
ERROR:__main__:Error in check_queue: '_tkinter.tkapp' object has no attribute 'update_progress'
Traceback (most recent call last):
  File "C:\Git\Repositories\Privat\BC-App-Updater\main.py", line 456, in check_queue
    self.update_progress(f"{status} {server_name}: {message}")
    ^^^^^^^^^^^^^^^^^^^^
  File "C:\Users\yannick.opitz\AppData\Local\Programs\Python\Python314\Lib\tkinter\__init__.py", line 2548, in __getattr__
    return getattr(self.tk, attr)
AttributeError: '_tkinter.tkapp' object has no attribute 'update_progress'

Exception in Tkinter callback
Traceback (most recent call last):
  File "C:\Git\Repositories\Privat\BC-App-Updater\main.py", line 456, in check_queue
    self.update_progress(f"{status} {server_name}: {message}")
    ^^^^^^^^^^^^^^^^^^^^
  File "C:\Users\yannick.opitz\AppData\Local\Programs\Python\Python314\Lib\tkinter\__init__.py", line 2548, in __getattr__
    return getattr(self.tk, attr)
AttributeError: '_tkinter.tkapp' object has no attribute 'update_progress'

During handling of the above exception, another exception occurred:

Traceback (most recent call last):
  File "C:\Users\yannick.opitz\AppData\Local\Programs\Python\Python314\Lib\tkinter\__init__.py", line 2070, in __call__
    return self.func(*args)
           ~~~~~~~~~^^^^^^^
  File "C:\Users\yannick.opitz\AppData\Local\Programs\Python\Python314\Lib\tkinter\__init__.py", line 864, in callit
    func(*args)
    ~~~~^^^^^^^
  File "C:\Git\Repositories\Privat\BC-App-Updater\main.py", line 488, in check_queue
    self.update_progress(f"Error checking progress: {str(e)}")
    ^^^^^^^^^^^^^^^^^^^^
  File "C:\Users\yannick.opitz\AppData\Local\Programs\Python\Python314\Lib\tkinter\__init__.py", line 2548, in __getattr__
    return getattr(self.tk, attr)
AttributeError: '_tkinter.tkapp' object has no attribute 'update_progress'